<?xml version="1.0" encoding="utf-8"?>
<!-- This URDF was automatically created by SolidWorks to URDF Exporter! Originally created by Stephen Brawner (brawner@gmail.com) 
     Commit Version: 1.6.0-4-g7f85cfe  Build Version: 1.6.7995.38578
     For more information, please see http://wiki.ros.org/sw_urdf_exporter -->
<robot
  name="description_omni_robot">
  <link
    name="base_link">
    <inertial>
      <origin
        xyz="5.14879102063576E-05 -1.74137783845452E-07 0.0274553941635394"
        rpy="0 0 0" />
      <mass
        value="0.82739544504234" />
      <inertia
        ixx="0.00126971978503133"
        ixy="4.9819065060905E-09"
        ixz="-9.85690620060945E-07"
        iyy="0.00127069403946336"
        iyz="-1.10887884890718E-08"
        izz="0.00223743741015236" />
    </inertial>
    <visual>
      <origin
        xyz="0 0 0"
        rpy="0 0 0" />
      <geometry>
        <mesh
          filename="package://description_omni_robot/meshes/base_link.STL" />
      </geometry>
      <material
        name="">
        <color
          rgba="0.792156862745098 0.819607843137255 0.933333333333333 1" />
      </material>
    </visual>
    <collision>
      <origin
        xyz="0 0 0"
        rpy="0 0 0" />
      <geometry>
        <mesh
          filename="package://description_omni_robot/meshes/base_link.STL" />
      </geometry>
    </collision>
  </link>

   <!-- wheel_1_link -->
  <link
    name="wheel_1_link">
    <inertial>
      <origin
        xyz="-7.73331428324808E-07 1.36449829682764E-06 0.00250496373629692"
        rpy="0 0 0" />
      <mass
        value="0.0573416524778109" />
      <inertia
        ixx="1.13223293501509E-05"
        ixy="-2.95114804266276E-09"
        ixz="3.32124175338235E-10"
        iyy="1.13254060867275E-05"
        iyz="-5.85053909828597E-10"
        izz="2.10837781325331E-05" />
    </inertial>
    <visual>
      <origin
        xyz="0 0 0"
        rpy="0 0 0" />
      <geometry>
        <mesh
          filename="package://description_omni_robot/meshes/wheel_1_link.STL" />
      </geometry>
      <material
        name="">
        <color
          rgba="0.498039215686275 0.498039215686275 0.498039215686275 1" />
      </material>
    </visual>
    <collision>
      <origin
        xyz="0 0 0"
        rpy="0 0 0" />
      <geometry>
        <mesh
          filename="package://description_omni_robot/meshes/wheel_1_link.STL" />
      </geometry>
    </collision>
  </link>

  <!-- wheel_1_joint -->
  <joint
    name="wheel_1_joint"
    type="continuous">
    <origin
      xyz="0 -0.100246212024587 0.0205"
      rpy="1.57079632679491 0 0" />
    <parent
      link="base_link" />
    <child
      link="wheel_1_link" />
    <axis
      xyz="0 0 1" />
  </joint>

  <!-- wheel_2_link -->
  <link
    name="wheel_2_link">
    <inertial>
      <origin
        xyz="-7.17667867591865E-07 -1.39141786774724E-06 0.00250496280406026"
        rpy="0 0 0" />
      <mass
        value="0.0573416543957745" />
      <inertia
        ixx="1.1322094172155E-05"
        ixy="2.81602792280319E-09"
        ixz="3.07984717324648E-10"
        iyy="1.13256412752839E-05"
        iyz="5.98180667761237E-10"
        izz="2.10837781360202E-05" />
    </inertial>
    <visual>
      <origin
        xyz="0 0 0"
        rpy="0 0 0" />
      <geometry>
        <mesh
          filename="package://description_omni_robot/meshes/wheel_2_link.STL" />
      </geometry>
      <material
        name="">
        <color
          rgba="0.498039215686275 0.498039215686275 0.498039215686275 1" />
      </material>
    </visual>
    <collision>
      <origin
        xyz="0 0 0"
        rpy="0 0 0" />
      <geometry>
        <mesh
          filename="package://description_omni_robot/meshes/wheel_2_link.STL" />
      </geometry>
    </collision>
  </link>

  <!-- wheel_2_joint -->
  <joint
    name="wheel_2_joint"
    type="continuous">
    <origin
      xyz="0 0.100246212024587 0.0205"
      rpy="-1.5707963267949 0 0" />
    <parent
      link="base_link" />
    <child
      link="wheel_2_link" />
    <axis
      xyz="0 0 1" />
  </joint>

  <!-- wheel_3_link -->
  <link
    name="wheel_3_link">
    <inertial>
      <origin
        xyz="1.51908366140263E-06 3.88345460327483E-07 0.00250496393125138"
        rpy="0 0 0" />
      <mass
        value="0.0573416520711861" />
      <inertia
        ixx="1.13268774307609E-05"
        ixy="1.42026119981074E-09"
        ixz="-6.51892959611491E-10"
        iyy="1.13208580119281E-05"
        iyz="-1.66006995153961E-10"
        izz="2.10837781377862E-05" />
    </inertial>
    <visual>
      <origin
        xyz="0 0 0"
        rpy="0 0 0" />
      <geometry>
        <mesh
          filename="package://description_omni_robot/meshes/wheel_3_link.STL" />
      </geometry>
      <material
        name="">
        <color
          rgba="0.498039215686275 0.498039215686275 0.498039215686275 1" />
      </material>
    </visual>
    <collision>
      <origin
        xyz="0 0 0"
        rpy="0 0 0" />
      <geometry>
        <mesh
          filename="package://description_omni_robot/meshes/wheel_3_link.STL" />
      </geometry>
    </collision>
  </link>

  <!-- wheel_3_joint -->
  <joint
    name="wheel_3_joint"
    type="continuous">
    <origin
      xyz="0.100246212024587 0 0.0205"
      rpy="-1.5707963267949 0 -1.5707963267949" />
    <parent
      link="base_link" />
    <child
      link="wheel_3_link" />
    <axis
      xyz="0 0 1" />
  </joint>

  <!-- wheel_4_link -->
  <link
    name="wheel_4_link">
    <inertial>
      <origin
        xyz="5.93270891080522E-07 1.45176169149414E-06 0.00250496284038054"
        rpy="0 0 0" />
      <mass
        value="0.0573416543210749" />
      <inertia
        ixx="1.13216344271888E-05"
        ixy="2.46736600754738E-09"
        ixz="-2.54928006960283E-10"
        iyy="1.13261010157933E-05"
        iyz="-6.22521577202815E-10"
        izz="2.1083778134734E-05" />
    </inertial>
    <visual>
      <origin
        xyz="0 0 0"
        rpy="0 0 0" />
      <geometry>
        <mesh
          filename="package://description_omni_robot/meshes/wheel_4_link.STL" />
      </geometry>
      <material
        name="">
        <color
          rgba="0.498039215686275 0.498039215686275 0.498039215686275 1" />
      </material>
    </visual>
    <collision>
      <origin
        xyz="0 0 0"
        rpy="0 0 0" />
      <geometry>
        <mesh
          filename="package://description_omni_robot/meshes/wheel_4_link.STL" />
      </geometry>
    </collision>
  </link>

  <!-- wheel_4_joint -->
  <joint
    name="wheel_4_joint"
    type="continuous">
    <origin
      xyz="-0.100246212024587 0 0.0205"
      rpy="-1.5707963267949 0 1.57079632679491" />
    <parent
      link="base_link" />
    <child
      link="wheel_4_link" />
    <axis
      xyz="0 0 1" />
  </joint>

  <!-- camera_link -->
  <link
    name="camera_link">
    <inertial>
      <origin
        xyz="0.000590757244492469 0.000225284785262264 0.00159615208822683"
        rpy="0 0 0" />
      <mass
        value="0.00154848311785293" />
      <inertia
        ixx="9.81433995869744E-08"
        ixy="1.55151579933954E-11"
        ixz="2.74786653138131E-09"
        iyy="6.15272705564258E-08"
        iyz="3.76721137527359E-10"
        izz="5.63299136111501E-08" />
    </inertial>
    <visual>
      <origin
        xyz="0 0 0"
        rpy="0 0 0" />
      <geometry>
        <mesh
          filename="package://description_omni_robot/meshes/camera_link.STL" />
      </geometry>
      <material
        name="">
        <color
          rgba="0.792156862745098 0.819607843137255 0.933333333333333 1" />
      </material>
    </visual>
    <collision>
      <origin
        xyz="0 0 0"
        rpy="0 0 0" />
      <geometry>
        <mesh
          filename="package://description_omni_robot/meshes/camera_link.STL" />
      </geometry>
    </collision>
  </link>

  <!-- camera_joint -->
  <joint
    name="camera_joint"
    type="fixed">
    <origin
      xyz="0.0712462120245874 -0.00019894784923466 0.0677413009524857"
      rpy="0 0 0" />
    <parent
      link="base_link" />
    <child
      link="camera_link" />
    <axis
      xyz="0 0 0" />
  </joint>

  <!-- arm_1 -->
  <link
    name="arm_1_link">
    <inertial>
      <origin
        xyz="-0.00156400679897185 -0.0368950468782312 -0.00640740431699427"
        rpy="0 0 0" />
      <mass
        value="0.0143340992877115" />
      <inertia
        ixx="1.14190389667868E-05"
        ixy="-8.56747187757367E-07"
        ixz="4.45382074543421E-09"
        iyy="5.72383802934529E-07"
        iyz="9.36344850652778E-08"
        izz="1.18300322472014E-05" />
    </inertial>
    <visual>
      <origin
        xyz="0 0 0"
        rpy="0 0 0" />
      <geometry>
        <mesh
          filename="package://description_omni_robot/meshes/arm_1_link.STL" />
      </geometry>
      <material
        name="">
        <color
          rgba="1 1 1 1" />
      </material>
    </visual>
    <collision>
      <origin
        xyz="0 0 0"
        rpy="0 0 0" />
      <geometry>
        <mesh
          filename="package://description_omni_robot/meshes/arm_1_link.STL" />
      </geometry>
    </collision>
  </link>
  <joint
    name="arm_1_joint"
    type="revolute">
    <origin
      xyz="0 0 0.098"
      rpy="-1.5707963267949 0 -0.0385348275356276" />
    <parent
      link="base_link" />
    <child
      link="arm_1_link" />
    <axis
      xyz="0.0595744481867079 0 -0.998223865234272" />
    <limit
      lower="-1.5707963267949"
      upper="1.5707963267949"
      effort="100"
      velocity="10" />
  </joint>

  <!-- arm_2 -->
  <link
    name="arm_2_link">
    <inertial>
      <origin
        xyz="0.0324879209871839 -0.0102485247399633 -0.00644610346251924"
        rpy="0 0 0" />
      <mass
        value="0.012131151928641" />
      <inertia
        ixx="1.48314951644483E-06"
        ixy="3.13729891623085E-06"
        ixz="-7.72880143623611E-08"
        iyy="9.17646027315437E-06"
        iyz="2.43810275892347E-08"
        izz="1.04619577493572E-05" />
    </inertial>
    <visual>
      <origin
        xyz="0 0 0"
        rpy="0 0 0" />
      <geometry>
        <mesh
          filename="package://description_omni_robot/meshes/arm_2_link.STL" />
      </geometry>
      <material
        name="">
        <color
          rgba="1 1 1 1" />
      </material>
    </visual>
    <collision>
      <origin
        xyz="0 0 0"
        rpy="0 0 0" />
      <geometry>
        <mesh
          filename="package://description_omni_robot/meshes/arm_2_link.STL" />
      </geometry>
    </collision>
  </link>
  <joint
    name="arm_2_joint"
    type="revolute">
    <origin
      xyz="-0.00753775193889759 -0.0846651185300513 -0.00750000000000012"
      rpy="0 0 0" />
    <parent
      link="arm_1_link" />
    <child
      link="arm_2_link" />
    <axis
      xyz="0.0595744481867083 0 -0.998223865234272" />
    <limit
      lower="-1.5707963267949"
      upper="1.5707963267949"
      effort="100"
      velocity="10" />
  </joint>

  <!-- imu -->
  <link
    name="imu_link">
    <inertial>
      <origin
        xyz="4.57501099858371E-05 -4.57501099858648E-05 0.000488343705367655"
        rpy="0 0 0" />
      <mass
        value="0.000302850245192701" />
      <inertia
        ixx="7.75930196249146E-09"
        ixy="-1.72720502873062E-09"
        ixz="6.34808961588483E-13"
        iyy="7.75930196249146E-09"
        iyz="-6.34808961588457E-13"
        izz="1.54683861524513E-08" />
    </inertial>
    <visual>
      <origin
        xyz="0 0 0"
        rpy="0 0 0" />
      <geometry>
        <mesh
          filename="package://description_omni_robot/meshes/imu_link.STL" />
      </geometry>
      <material
        name="">
        <color
          rgba="0.666666666666667 0.698039215686274 0.768627450980392 1" />
      </material>
    </visual>
    <collision>
      <origin
        xyz="0 0 0"
        rpy="0 0 0" />
      <geometry>
        <mesh
          filename="package://description_omni_robot/meshes/imu_link.STL" />
      </geometry>
    </collision>
  </link>
  <joint
    name="imu_joint"
    type="fixed">
    <origin
      xyz="-0.000173723647626037 0.000173723647625995 0.00400000000000001"
      rpy="0 0 0" />
    <parent
      link="base_link" />
    <child
      link="imu_link" />
    <axis
      xyz="0 0 0" />
  </joint>

  <!-- plugin cho camera -->
  <gazebo reference="camera_link">
    <sensor name="camera_sensor" type="camera">
      <always_on>1</always_on>
      <update_rate>30</update_rate>
      <camera>
        <horizontal_fov>1.0472</horizontal_fov>
        <image_width>640</image_width>
        <image_height>480</image_height>
        <near>0.1</near>
        <far>100</far>
      </camera>
      <plugin name="camera_plugin" filename="libgazebo_ros_camera.so">
        <topicName>/camera/image_raw</topicName>
        <cameraName>camera</cameraName>
        <frameName>camera_link</frameName>
      </plugin>
    </sensor>
  </gazebo>

  <!-- plugin cho imu -->
<gazebo reference="imu_link">
    <gravity>true</gravity>
    <sensor name="imu_sensor" type="imu">
      <always_on>true</always_on>
      <update_rate>100</update_rate>
      <visualize>true</visualize>
      <topic>__default_topic__</topic>
      <plugin filename="libgazebo_ros_imu_sensor.so" name="imu_plugin">
        <topicName>imu</topicName>
        <bodyName>imu_link</bodyName>
        <updateRateHZ>10.0</updateRateHZ>
        <gaussianNoise>0.0</gaussianNoise>
        <xyzOffset>0 0 0</xyzOffset>
        <rpyOffset>0 0 0</rpyOffset>
        <frameName>imu_link</frameName>
        <initialOrientationAsReference>false</initialOrientationAsReference>
      </plugin>
      <pose>0 0 0 0 0 0</pose>
    </sensor>
  </gazebo>
  
  <!-- transmission for 2 arm  -->
   
  <transmission name="arm_1_joint_transmission">
    <type>transmission_interface/SimpleTransmission</type>
    <joint name="arm_1_joint">
      <hardwareInterface>hardware_interface/PositionJointInterface</hardwareInterface>
    </joint>
    <actuator name="arm_1">
      <mechanicalReduction>1.0</mechanicalReduction>
    </actuator>
  </transmission>

  <transmission name="arm_2_joint_transmission">
    <type>transmission_interface/SimpleTransmission</type>
    <joint name="arm_2_joint">
      <hardwareInterface>hardware_interface/PositionJointInterface</hardwareInterface>
    </joint>
    <actuator name="arm_2">
      <mechanicalReduction>1.0</mechanicalReduction>
    </actuator>
  </transmission>

  <!-- transmission for 4 wheel -->
  
  <transmission name="tran_wheel_1">
    <type>transmission_interface/SimpleTransmission</type>
    <joint name="wheel_1_joint">
      <hardwareInterface>hardware_interface/VelocityJointInterface</hardwareInterface>
    </joint>
    <actuator name="wheel_1_motor">
      <mechanicalReduction>1</mechanicalReduction>
    </actuator>
  </transmission>

  <transmission name="tran_wheel_2">
    <type>transmission_interface/SimpleTransmission</type>
    <joint name="wheel_2_joint">
      <hardwareInterface>hardware_interface/VelocityJointInterface</hardwareInterface>
    </joint>
    <actuator name="wheel_2_motor">
      <mechanicalReduction>1</mechanicalReduction>
    </actuator>
  </transmission>

  <transmission name="tran_wheel_3">
    <type>transmission_interface/SimpleTransmission</type>
    <joint name="wheel_3_joint">
      <hardwareInterface>hardware_interface/VelocityJointInterface</hardwareInterface>
    </joint>
    <actuator name="wheel_3_motor">
      <mechanicalReduction>1</mechanicalReduction>
    </actuator>
  </transmission>

  <transmission name="tran_wheel_4">
    <type>transmission_interface/SimpleTransmission</type>
    <joint name="wheel_4_joint">
      <hardwareInterface>hardware_interface/VelocityJointInterface</hardwareInterface>
    </joint>
    <actuator name="wheel_4_motor">
      <mechanicalReduction>1</mechanicalReduction>
    </actuator>
  </transmission>

  <!-- plugin gazebo control -->
  <gazebo>
    <plugin name ="gazebo_ros_control" filename = "libgazebo_ros_control.so">
        <robotNamespace>/</robotNamespace>
    </plugin>
  </gazebo>



</robot>
